<?xml version="1.0"?>
<robot xmlns:xacro="http://www.ros.org/wiki/xacro" name="pfr_robot">
  
  <xacro:include filename="$(find robot_description)/gazebo/robot.gazebo.xacro" />
  <xacro:include filename="$(find robot_description)/ros2_control/robot.ros2_control.xacro" />

    <material name="ChassisMaterial">
        <color rgba="0.6 0.6 0.6 1"/>
    </material>

    <material name="ForkMaterial">
        <color rgba="0.0 0.5 0.0 1"/> <!-- Medium green -->
    </material>

    <material name="WheelMaterial">
        <color rgba="0.2 0.2 0.2 1"/>
    </material>

<!-- Links -->
  <link name="base_footprint"> </link>
  <joint name="body_link_joint" type="fixed">
    <parent link="base_footprint"/>
    <child link="base_link"/>
    <origin xyz="0 0 0.6" rpy="0 0 0"/>
  </joint>

    <!-- Chassis -->
    <link name="base_link">
        <inertial>
            <origin rpy="0 0 0" xyz="0 0 0"/>
            <mass value="31.726"/>
            <inertia ixx="14.69967178219" ixy="9.034e-14" ixz="1.250e-13" 
                     iyy="18.23" iyz="3.749e-12" izz="31.10"/>
        </inertial>
        <visual>
            <origin rpy="0 0 0" xyz="0 0 0"/>
            <geometry>
                <mesh filename="package://robot_description/meshes/frame_assembly.stl"/>
            </geometry>
            <material name="ChassisMaterial"/>
        </visual>
        <collision>
            <origin rpy="0 0 0" xyz="0 0 0"/>
            <geometry>
                <mesh filename="package://robot_description/meshes/frame_assembly.stl"/>
            </geometry>
        </collision>
    </link>


<!-- Forks -->

    <link name="front_right_fork">
        <inertial>
            <mass value="20.664"/>
            <inertia ixx="0.748741229" ixy="0.017262554" ixz="-0.011181714" 
                     iyy="0.577270351" iyz="0.044985592" izz="0.577720988"/>
        </inertial>
        <visual>
            <geometry>
                <mesh filename="package://robot_description/meshes/fork_assembly.stl"/>
            </geometry>
            <material name="ForkMaterial"/>
        </visual>
        <collision>
            <geometry>
                <mesh filename="package://robot_description/meshes/fork_assembly.stl"/>
            </geometry>
        </collision>
    </link>

    <link name="front_left_fork">
        <inertial>
            <mass value="20.664"/>
            <inertia ixx="0.748741229" ixy="0.017262554" ixz="-0.011181714" 
                     iyy="0.577270351" iyz="0.044985592" izz="0.577720988"/>
        </inertial>
        <visual>
            <geometry>
                <mesh filename="package://robot_description/meshes/fork_assembly.stl"/>
            </geometry>
            <material name="ForkMaterial"/>
        </visual>
        <collision>
            <geometry>
                <mesh filename="package://robot_description/meshes/fork_assembly.stl"/>
            </geometry>
        </collision>
    </link>

    <link name="rear_right_fork">
        <inertial>
            <mass value="20.664"/>
            <inertia ixx="0.748741229" ixy="0.017262554" ixz="-0.011181714" 
                     iyy="0.577270351" iyz="0.044985592" izz="0.577720988"/>
        </inertial>
        <visual>
            <geometry>
                <mesh filename="package://robot_description/meshes/fork_assembly.stl"/>
            </geometry>
            <material name="ForkMaterial"/>
        </visual>
        <collision>
            <geometry>
                <mesh filename="package://robot_description/meshes/fork_assembly.stl"/>
            </geometry>
        </collision>
    </link>

    <link name="rear_left_fork">
        <inertial>
            <mass value="20.664"/>
            <inertia ixx="0.748741229" ixy="0.017262554" ixz="-0.011181714" 
                     iyy="0.577270351" iyz="0.044985592" izz="0.577720988"/>
        </inertial>
        <visual>
            <geometry>
                <mesh filename="package://robot_description/meshes/fork_assembly.stl"/>
            </geometry>
            <material name="ForkMaterial"/>
        </visual>
        <collision>
            <geometry>
                <mesh filename="package://robot_description/meshes/fork_assembly.stl"/>
            </geometry>
        </collision>
    </link>

<!-- Wheels -->

    <link name="front_right_wheel">
        <inertial>
            <mass value="18.825"/>
            <inertia ixx="0.51318866" ixy="-6.46e-7" ixz="-3.08e-7" 
                     iyy="0.513187519" iyz="-8.3026e-5" izz="0.98574484"/>
        </inertial>
        <visual>
            <geometry>
                <mesh filename="package://robot_description/meshes/wheel_assembly.stl"/>
            </geometry>
            <material name="WheelMaterial"/>
        </visual>
        <collision>
            <geometry>
                <mesh filename="package://robot_description/meshes/wheel_assembly.stl"/>
            </geometry>
        </collision>
    </link>    

    <link name="front_left_wheel">
        <inertial>
            <mass value="18.825"/>
            <inertia ixx="0.51318866" ixy="-6.46e-7" ixz="-3.08e-7" 
                     iyy="0.513187519" iyz="-8.3026e-5" izz="0.98574484"/>
        </inertial>
        <visual>
            <geometry>
                <mesh filename="package://robot_description/meshes/wheel_assembly.stl"/>
            </geometry>
            <material name="WheelMaterial"/>
        </visual>
        <collision>
            <geometry>
                <mesh filename="package://robot_description/meshes/wheel_assembly.stl"/>
            </geometry>
        </collision>
    </link>    

    <link name="rear_right_wheel">
        <inertial>
            <mass value="18.825"/>
            <inertia ixx="0.51318866" ixy="-6.46e-7" ixz="-3.08e-7" 
                     iyy="0.513187519" iyz="-8.3026e-5" izz="0.98574484"/>
        </inertial>
        <visual>
            <geometry>
                <mesh filename="package://robot_description/meshes/wheel_assembly.stl"/>
            </geometry>
            <material name="WheelMaterial"/>
        </visual>
        <collision>
            <geometry>
                <mesh filename="package://robot_description/meshes/wheel_assembly.stl"/>
            </geometry>
        </collision>
    </link>    

    <link name="rear_left_wheel">
        <inertial>
            <mass value="18.825"/>
            <inertia ixx="0.51318866" ixy="-6.46e-7" ixz="-3.08e-7" 
                     iyy="0.513187519" iyz="-8.3026e-5" izz="0.98574484"/>
        </inertial>
        <visual>
            <geometry>
                <mesh filename="package://robot_description/meshes/wheel_assembly.stl"/>
            </geometry>
            <material name="WheelMaterial"/>
        </visual>
        <collision>
            <geometry>
                <mesh filename="package://robot_description/meshes/wheel_assembly.stl"/>
            </geometry>
        </collision>
    </link>    

<!-- Joints -->

    <joint name="front_right_fork_joint" type="revolute">
        <parent link="base_link"/>
        <child link="front_right_fork"/>
        <origin xyz="0.75 -0.78 -0.42" rpy="0 0 1.571"/>
        <axis xyz="0 0 1"/>
        <limit lower="-3.14159" upper="3.14159" effort="10" velocity="1.0"/>
    </joint>

    <joint name="front_left_fork_joint" type="revolute">
        <parent link="base_link"/>
        <child link="front_left_fork"/>
        <origin xyz="0.75 0.78 -0.42" rpy="0 0 1.571"/>
        <axis xyz="0 0 1"/>
        <limit lower="-3.14159" upper="3.14159" effort="10" velocity="1.0"/>
    </joint>

    <joint name="rear_right_fork_joint" type="revolute">
        <parent link="base_link"/>
        <child link="rear_right_fork"/>
        <origin xyz="-0.75 -0.78 -0.42" rpy="0 0 1.571"/>
        <axis xyz="0 0 1"/>
        <limit lower="-3.14159" upper="3.14159" effort="10" velocity="1.0"/>
    </joint>

    <joint name="rear_left_fork_joint" type="revolute">
        <parent link="base_link"/>
        <child link="rear_left_fork"/>
        <origin xyz="-0.75 0.78 -0.42" rpy="0 0 1.571"/>
        <axis xyz="0 0 1"/>
        <limit lower="-3.14159" upper="3.14159" effort="10" velocity="1.0"/>
    </joint>

    <joint name="front_right_wheel_joint" type="revolute">
        <parent link="front_right_fork"/>
        <child link="front_right_wheel"/>
        <origin xyz="0 0 -0.31" rpy="0 1.571 0"/> 
        <axis xyz="0 0 1"/>
        <limit lower="-1e10" upper="1e10" effort="150" velocity="30.0"/>
    </joint>

    <joint name="front_left_wheel_joint" type="revolute">
        <parent link="front_left_fork"/>
        <child link="front_left_wheel"/>
        <origin xyz="0 0 -0.31" rpy="0 1.571 0"/> 
        <axis xyz="0 0 1"/>
        <limit lower="-1e10" upper="1e10" effort="150" velocity="30.0"/>
    </joint>

    <joint name="rear_right_wheel_joint" type="revolute">
        <parent link="rear_right_fork"/>
        <child link="rear_right_wheel"/>
        <origin xyz="0 0 -0.31" rpy="0 1.571 0"/> 
        <axis xyz="0 0 1"/>
        <limit lower="-1e10" upper="1e10" effort="150" velocity="30.0"/>
    </joint>

    <joint name="rear_left_wheel_joint" type="revolute">
        <parent link="rear_left_fork"/>
        <child link="rear_left_wheel"/>
        <origin xyz="0 0 -0.31" rpy="0 1.571 0"/> 
        <axis xyz="0 0 1"/>
        <limit lower="-1e10" upper="1e10" effort="150" velocity="30.0"/>
    </joint>

    <!-- Gazebo Parameters -->
    <gazebo reference="base_link">
        <mu1>1.0</mu1>
        <mu2>1.0</mu2>
    </gazebo>

    <gazebo reference="right_wheel_link">
        <mu1>1.0</mu1>
        <mu2>1.0</mu2>
    </gazebo>

    <gazebo reference="left_wheel_link">
        <mu1>1.0</mu1>
        <mu2>1.0</mu2>
    </gazebo>

    <gazebo reference="right_back_wheel_link">
        <mu1>0.0001</mu1>
        <mu2>0.0001</mu2>
    </gazebo>

    <gazebo reference="left_back_wheel_link">
        <mu1>0.0001</mu1>
        <mu2>0.0001</mu2>
    </gazebo>


  <xacro:robot_gazebo/>
  <xacro:robot_ros2_control/>
    
</robot>
